Workbook

Sheet Cover
C4: IDFC FIRST Bank Ltd.
C6: Three-Statement Financial Model (Standalone, INR crore) – FY2022A–FY2031F
C11: Table of Contents | K11: Model Checks
N12: Flag
C13: Outputs | D13: Dashboard: key metrics and charts | K13: Balance Sheet Unbalanced? | N13: =IF(SUM(Model!$F$315:$O$315)>0,1,0) -> 0
C14: Inputs | D14: Scenario drivers (Best / Base / Worst) and other assumptions | K14: Cash Flow ≠ Balance Sheet Cash? | N14: =IF(SUM(Model!$F$316:$O$316)>0,1,0) -> 0
C15: Model | D15: Income statement, cash flow, balance sheet, supporting schedules and checks | K15: Reserves Roll-forward Break? | N15: =IF(SUM(Model!$F$317:$O$317)>0,1,0) -> 0
C16: Historicals | D16: Reported standalone financials FY22–FY26 with source notes | K16: Advances Schedule ≠ Balance Sheet? | N16: =IF(SUM(Model!$F$318:$O$318)>0,1,0) -> 0
C17: DCF Valuation | D17: Equity valuation via residual income model (equity DCF), CAPM cost of equity and sensitivities | K17: Deposits Schedule ≠ Balance Sheet? | N17: =IF(SUM(Model!$F$319:$O$319)>0,1,0) -> 0
C18: Comparable Company Analysis | D18: Peer P/B & P/E multiples, implied price and sensitivities | K18: Borrowings Schedule ≠ Balance Sheet? | N18: =IF(SUM(Model!$F$320:$O$320)>0,1,0) -> 0
K19: Historical PAT ≠ Reported? | N19: =IF(SUM(Model!$F$321:$O$321)>0,1,0) -> 0
C20: Scenario Running | K20: Historical Total Assets ≠ Reported? | N20: =IF(SUM(Model!$F$322:$O$322)>0,1,0) -> 0
C21: {=INDEX(Inputs!$B$11:$B$13,Inputs!$E$6)&" (change on Inputs!E7: 1 = Best, 2 = Base, 3 = Worst)"} -> Base Case (change on Inputs!E7: 1 = Best, 2 = Base, 3 = Worst) | K21: Capital Below Regulatory Minimum? | N21: =IF(SUM(Model!$F$323:$O$323)>0,1,0) -> 0
K22: Negative Bank Balances? | N22: =IF(SUM(Model!$F$324:$O$324)>0,1,0) -> 0
C23: Key Conventions | K23: Hard-coded Forecast Cells in Statements? | N23: =IF(SUM(Model!$F$325:$O$325)>0,1,0) -> 0
C24: • Blue = hard-coded inputs and reported data; black = formulas; green = links from other sheets. | K24: Error Values in Model? | N24: =IF(SUM(Model!$F$326:$O$326)>0,1,0) -> 0
C25: • Fiscal year ends 31 March (2026A = FY2025-26). Actuals are standalone audited figures. | K25: Valuation Integrity Issue? | N25: ='DCF Valuation'!$F$110 -> 0
C26: • Cash is derived from the cash flow statement; a liquidity facility (CFI revolver logic) funds any shortfall below minimum cash. | K26: OVERALL MODEL STATUS | N26: =IF(SUM(N13:N25)+N27=0,"OK","CHECK") -> OK
C27: • No circular references: interest on cash and the liquidity facility uses opening balances. | K27: Comparable Company Analysis Issue? | N27: ='Comparable Company Analysis'!$F$112 -> 0
C28: • Depreciation sits within other operating expenses (RBI format) and is added back in the cash flow.
C31: Primary Sources
C32: • IDFC FIRST Bank – Audited Standalone Financial Results Q4 FY26 (25-Apr-2026): FY25, FY26
C33: • IDFC FIRST Bank – Audited Standalone Financial Results Q4 FY24 (27-Apr-2024): FY24
C34: • IDFC FIRST Bank – Audited Standalone Financial Results Q4 FY23 (29-Apr-2023): FY22, FY23
C35: • IDFC FIRST Bank – Investor Presentation Q4 FY26: CASA, CET1, RWA, Tier 2; Q4 FY26 earnings call: guidance
C36: • Cell-level source notes and URLs are on the Historicals tab.
C38: Model structure adapted from CFI Education Inc. Three-Statement Model template (© 2015–2024 CFI Education Inc.). For analysis purposes only; not investment advice.

Sheet Outputs
B3: Dashboard: Key Metrics & Charts
B5: All figures in INR crore unless stated | F5: =Model!F$5 -> 2022 | G5: =Model!G$5 -> 2023 | H5: =Model!H$5 -> 2024 | I5: =Model!I$5 -> 2025 | J5: =Model!J$5 -> 2026 | K5: =Model!K$5 -> 2027 | L5: =Model!L$5 -> 2028 | M5: =Model!M$5 -> 2029 | ... O5: =Model!O$5 -> 2031
B6: =Model!B6 -> Model Running: Base Case Drivers
B8: INCOME STATEMENT
B9: Net Interest Income | F9: =Model!F16 -> 9706.16 | G9: =Model!G16 -> 12635.33 | H9: =Model!H16 -> 16450.75 | I9: =Model!I16 -> 19291.97 | J9: =Model!J16 -> 21215.27 | K9: =Model!K16 -> 25487.518 | L9: =Model!L16 -> 30364.915 | M9: =Model!M16 -> 35878.576 | ... O9: =Model!O16 -> 49560.942
B10: Other Income | F10: =Model!F18 -> 3222.04 | G10: =Model!G18 -> 4466.97 | H10: =Model!H18 -> 6002 | I10: =Model!I18 -> 7021.71 | J10: =Model!J18 -> 7873.29 | K10: =Model!K18 -> 9290.4822 | L10: =Model!L18 -> 10869.864 | M10: =Model!M18 -> 12609.042 | ... O10: =Model!O18 -> 16675.459
B11: Operating Profit (PPOP) | F11: =Model!F24 -> 3283.75 | G11: =Model!G24 -> 4931.95 | H11: =Model!H24 -> 6236.97 | I11: =Model!I24 -> 7414.85 | J11: =Model!J24 -> 7211.36 | K11: =Model!K24 -> 9837.9917 | L11: =Model!L24 -> 13052.57 | M11: =Model!M24 -> 16641.722 | ... O11: =Model!O24 -> 26288.909
B12: Provisions & Contingencies | F12: =-Model!F26 -> 3108.58 | G12: =-Model!G26 -> 1664.82 | H12: =-Model!H26 -> 2381.65 | I12: =-Model!I26 -> 5514.73 | J12: =-Model!J26 -> 5378.55 | K12: =-Model!K26 -> 5397.519 | L12: =-Model!L26 -> 6106.9073 | M12: =-Model!M26 -> 7073.9184 | ... O12: =-Model!O26 -> 9534.9045
B13: Net Profit (PAT) | F13: =Model!F30 -> 145.49 | G13: =Model!G30 -> 2437.13 | H13: =Model!H30 -> 2956.51 | I13: =Model!I30 -> 1524.85 | J13: =Model!J30 -> 1636.36 | K13: =Model!K30 -> 3322.8057 | L13: =Model!L30 -> 5197.4394 | M13: =Model!M30 -> 7159.5873 | ... O13: =Model!O30 -> 12537.022
B15: BALANCE SHEET
B16: Net Advances | F16: =Model!F87 -> 117857.8 | G16: =Model!G87 -> 151794.53 | H16: =Model!H87 -> 194592.37 | I16: =Model!I87 -> 233112.53 | J16: =Model!J87 -> 280390.6 | K16: =Model!K87 -> 336468.72 | L16: =Model!L87 -> 403762.46 | M16: =Model!M87 -> 480477.33 | ... O16: =Model!O87 -> 663347
B17: Deposits | F17: =Model!F93 -> 105634.36 | G17: =Model!G93 -> 144637.31 | H17: =Model!H93 -> 200576.31 | I17: =Model!I93 -> 252065.25 | J17: =Model!J93 -> 294474.55 | K17: =Model!K93 -> 359258.95 | L17: =Model!L93 -> 434703.33 | M17: =Model!M93 -> 521644 | ... O17: =Model!O93 -> 732492.5
B18: Total Assets | F18: =Model!F90 -> 190181.61 | G18: =Model!G90 -> 239941.66 | H18: =Model!H90 -> 296115.1 | I18: =Model!I90 -> 343818.65 | J18: =Model!J90 -> 399780.09 | K18: =Model!K90 -> 475995.09 | L18: =Model!L90 -> 573728.17 | M18: =Model!M90 -> 681677.83 | ... O18: =Model!O90 -> 946795.4
B19: Shareholders' Funds | F19: =Model!F101 -> 21003.48 | G19: =Model!G101 -> 25721.17 | H19: =Model!H101 -> 32161.31 | I19: =Model!I101 -> 38078 | J19: =Model!J101 -> 47351.84 | K19: =Model!K101 -> 50459.603 | L19: =Model!L101 -> 62658.622 | M19: =Model!M101 -> 69038.593 | ... O19: =Model!O101 -> 98490.275
B21: KEY RATIOS
B22: Net Interest Margin (calc.) | F22: =Model!F33 -> 0 | G22: =Model!G33 -> 0.062154734 | H22: =Model!H33 -> 0.064690452 | I22: =Model!I33 -> 0.063178992 | J22: =Model!J33 -> 0.059926362 | K22: =Model!K33 -> 0.06124252 | L22: =Model!L33 -> 0.060726649 | M22: =Model!M33 -> 0.059955703 | ... O22: =Model!O33 -> 0.059148212
B23: Cost-to-Income Ratio | F23: =Model!F34 -> 0.74600099 | G23: =Model!G34 -> 0.71162066 | H23: =Model!H34 -> 0.72221799 | I23: =Model!I34 -> 0.71821311 | J23: =Model!J34 -> 0.75208948 | K23: =Model!K34 -> 0.71712025 | L23: =Model!L34 -> 0.68345726 | M23: =Model!M34 -> 0.65678409 | ... O23: =Model!O34 -> 0.60310481
B24: Credit Cost | F24: =Model!F35 -> 0 | G24: =Model!G35 -> 0.0123479 | H24: =Model!H35 -> 0.013751386 | I24: =Model!I35 -> 0.025787547 | J24: =Model!J35 -> 0.02094846 | K24: =Model!K35 -> 0.0175 | L24: =Model!L35 -> 0.0165 | M24: =Model!M35 -> 0.016 | ... O24: =Model!O35 -> 0.0155
B25: Return on Assets | F25: =Model!F37 -> 0 | G25: =Model!G37 -> 0.01133224 | H25: =Model!H37 -> 0.011030586 | I25: =Model!I37 -> 0.0047656496 | J25: =Model!J37 -> 0.0044011909 | K25: =Model!K37 -> 0.0075882619 | L25: =Model!L37 -> 0.0099024945 | M25: =Model!M37 -> 0.011406011 | ... O25: =Model!O37 -> 0.01427914
B26: Return on Equity | F26: =Model!F38 -> 0 | G26: =Model!G38 -> 0.10431881 | H26: =Model!H38 -> 0.10215561 | I26: =Model!I38 -> 0.043418707 | J26: =Model!J38 -> 0.038308863 | K26: =Model!K38 -> 0.067943087 | L26: =Model!L38 -> 0.091893934 | M26: =Model!M38 -> 0.108728 | ... O26: =Model!O38 -> 0.1349131
B27: CASA Ratio | F27: =Model!F139 -> 0.48440678 | G27: =Model!G139 -> 0.49767933 | H27: =Model!H139 -> 0.47247853 | I27: =Model!I139 -> 0.46907299 | J27: =Model!J139 -> 0.49800569 | K27: =Model!K139 -> 0.5 | L27: =Model!L139 -> 0.505 | M27: =Model!M139 -> 0.51 | ... O27: =Model!O139 -> 0.52
B28: Gross NPA Ratio | F28: =Model!F119 -> 0.037 | G28: =Model!G119 -> 0.0251 | H28: =Model!H119 -> 0.0188 | I28: =Model!I119 -> 0.0187 | J28: =Model!J119 -> 0.0161 | K28: =Model!K119 -> 0.0155 | L28: =Model!L119 -> 0.015 | M28: =Model!M119 -> 0.0145 | ... O28: =Model!O119 -> 0.0145
B29: Net NPA Ratio | F29: =Model!F123 -> 0.0153 | G29: =Model!G123 -> 0.0086 | H29: =Model!H123 -> 0.006 | I29: =Model!I123 -> 0.0053 | J29: =Model!J123 -> 0.0048 | K29: =Model!K123 -> 0.0045450179 | L29: =Model!L123 -> 0.0042458552 | M29: =Model!M123 -> 0.0041028336 | ... O29: =Model!O123 -> 0.0041028336
B30: CET1 Ratio | F30: =Model!F302 -> 0 | G30: =Model!G302 -> 0 | H30: =Model!H302 -> 0 | I30: =Model!I302 -> 0.1317597 | J30: =Model!J302 -> 0.13727528 | K30: =Model!K302 -> 0.12235699 | L30: =Model!L302 -> 0.12605558 | M30: =Model!M302 -> 0.11689614 | ... O30: =Model!O302 -> 0.12006727
B31: CRAR | F31: =Model!F303 -> 0.1674 | G31: =Model!G303 -> 0.1682 | H31: =Model!H303 -> 0.1611 | I31: =Model!I303 -> 0.1548 | J31: =Model!J303 -> 0.156 | K31: =Model!K303 -> 0.13801474 | L31: =Model!L303 -> 0.13904608 | M31: =Model!M303 -> 0.12782948 | ... O31: =Model!O303 -> 0.1279391
B33: Charts: actuals FY22–FY26, forecasts FY27–FY31 (ratio charts start FY23 as averages need a prior year).

Sheet Inputs
B3: Drivers
B4: All figures in INR crore unless stated | F4: =$K$4-5 -> 2022 | G4: =$K$4-4 -> 2023 | H4: =$K$4-3 -> 2024 | I4: =$K$4-2 -> 2025 | J4: =$K$4-1 -> 2026 | K4: =$F$80 -> 2027 | L4: =$K$4+1 -> 2028 | M4: =$K$4+2 -> 2029 | N4: =$K$4+3 -> 2030 | O4: =$K$4+4 -> 2031 | Q4: Basis / source of assumption
B6: Driver Switch | E6: 2 | F6: {="Running: "&INDEX($B$11:$B$13,$E$6)&" (1 = Best, 2 = Base, 3 = Worst)"} -> Running: Base Case (1 = Best, 2 = Base, 3 = Worst)
B9: Advances Growth (YoY) | G9: =Model!G114 -> 0.28794641 | H9: =Model!H114 -> 0.28194586 | I9: =Model!I114 -> 0.19795309 | J9: =Model!J114 -> 0.20281222 | K9: {=INDEX(K11:K13,$E$6)} -> 0.2 | L9: {=INDEX(L11:L13,$E$6)} -> 0.2 | M9: {=INDEX(M11:M13,$E$6)} -> 0.19 | N9: {=INDEX(N11:N13,$E$6)} -> 0.18 | O9: {=INDEX(O11:O13,$E$6)} -> 0.17 | Q9: Mgmt guided ~20% loan growth for FY27 (Q4 FY26 call: back to ~5% QoQ); FY26 actual 20.3%. Gradual moderation as book scales.
B11: Best Case | K11: 0.22 | L11: 0.22 | M11: 0.21 | N11: 0.2 | O11: 0.19
B12: Base Case | K12: 0.2 | L12: 0.2 | M12: 0.19 | N12: 0.18 | O12: 0.17
B13: Worst Case | K13: 0.15 | L13: 0.15 | M13: 0.14 | N13: 0.14 | O13: 0.13
B16: Deposit Growth (YoY) | G16: =Model!G137 -> 0.36922598 | H16: =Model!H137 -> 0.3867536 | I16: =Model!I137 -> 0.25670499 | J16: =Model!J137 -> 0.16824731 | K16: {=INDEX(K18:K20,$E$6)} -> 0.22 | L16: {=INDEX(L18:L20,$E$6)} -> 0.21 | M16: {=INDEX(M18:M20,$E$6)} -> 0.2 | N16: {=INDEX(N18:N20,$E$6)} -> 0.19 | O16: {=INDEX(O18:O20,$E$6)} -> 0.18 | Q16: Deposits to grow slightly ahead of loans (mgmt: normalised deposit growth from Q1 FY27 after Q4 FY26 one-off); FY26 actual 16.8%, FY25 25.7%.
B18: =$B$11 -> Best Case | K18: 0.23 | L18: 0.22 | M18: 0.21 | N18: 0.2 | O18: 0.19
B19: =$B$12 -> Base Case | K19: 0.22 | L19: 0.21 | M19: 0.2 | N19: 0.19 | O19: 0.18
B20: =$B$13 -> Worst Case | K20: 0.17 | L20: 0.16 | M20: 0.15 | N20: 0.15 | O20: 0.14
B23: Yield on Advances (Interest / Avg Net Advances) | G23: =Model!G189 -> 0.14210432 | H23: =Model!H189 -> 0.14963551 | I23: =Model!I189 -> 0.14418596 | J23: =Model!J189 -> 0.13319736 | K23: {=INDEX(K25:K27,$E$6)} -> 0.131 | L23: {=INDEX(L25:L27,$E$6)} -> 0.13 | M23: {=INDEX(M25:M27,$E$6)} -> 0.129 | N23: {=INDEX(N25:N27,$E$6)} -> 0.128 | O23: {=INDEX(O25:O27,$E$6)} -> 0.128 | Q23: FY26 calculated 13.3%; mgmt cites book yield '13%+'. Mild compression from mix shift to secured / prime loans and lower policy rates.
B25: =$B$11 -> Best Case | K25: 0.132 | L25: 0.131 | M25: 0.13 | N25: 0.13 | O25: 0.13
B26: =$B$12 -> Base Case | K26: 0.131 | L26: 0.13 | M26: 0.129 | N26: 0.128 | O26: 0.128
B27: =$B$13 -> Worst Case | K27: 0.128 | L27: 0.126 | M27: 0.125 | N27: 0.124 | O27: 0.124
B30: Credit Cost (Provisions / Avg Net Advances) | G30: =Model!G127 -> 0.0123479 | H30: =Model!H127 -> 0.013751386 | I30: =Model!I127 -> 0.025787547 | J30: =Model!J127 -> 0.02094846 | K30: {=INDEX(K32:K34,$E$6)} -> 0.0175 | L30: {=INDEX(L32:L34,$E$6)} -> 0.0165 | M30: {=INDEX(M32:M34,$E$6)} -> 0.016 | N30: {=INDEX(N32:N34,$E$6)} -> 0.0155 | O30: {=INDEX(O32:O34,$E$6)} -> 0.0155 | Q30: FY26 reported credit cost 2.13% (calc. 2.09% on avg net advances). FY27 guidance 1.70–1.80% (Q4 FY26 call); later cut to 1.50–1.60% at Q1 FY27 (per call summaries – verify).
B32: =$B$11 -> Best Case | K32: 0.0155 | L32: 0.015 | M32: 0.0145 | N32: 0.014 | O32: 0.014
B33: =$B$12 -> Base Case | K33: 0.0175 | L33: 0.0165 | M33: 0.016 | N33: 0.0155 | O33: 0.0155
B34: =$B$13 -> Worst Case | K34: 0.022 | L34: 0.021 | M34: 0.02 | N34: 0.019 | O34: 0.019
B37: Other Inputs
B38: All figures in INR crore unless stated | F38: =$K$4-5 -> 2022 | G38: =$K$4-4 -> 2023 | H38: =$K$4-3 -> 2024 | I38: =$K$4-2 -> 2025 | J38: =$K$4-1 -> 2026 | K38: =$F$80 -> 2027 | L38: =$K$4+1 -> 2028 | M38: =$K$4+2 -> 2029 | N38: =$K$4+3 -> 2030 | O38: =$K$4+4 -> 2031 | Q38: Basis / source of assumption
B40: BALANCE SHEET & FUNDING
B41: CASA Ratio | F41: =Model!F139 -> 0.48440678 | G41: =Model!G139 -> 0.49767933 | H41: =Model!H139 -> 0.47247853 | I41: =Model!I139 -> 0.46907299 | J41: =Model!J139 -> 0.49800569 | K41: 0.5 | L41: 0.505 | M41: 0.51 | N41: 0.515 | O41: 0.52 | Q41: Mar-26 CASA ratio 49.8% (Investor Presentation Q4 FY26); avg CASA ratio 50.4% in Q4 FY26. Gradual improvement assumed.
B42: Borrowings Growth (Scheduled) | G42: =Model!G146 -> 0.080235676 | H42: =Model!H146 -> -0.10970618 | I42: =Model!I146 -> -0.23482077 | J42: =Model!J146 -> -0.060402044 | K42: 0.12 | L42: 0.12 | M42: 0.12 | N42: 0.12 | O42: 0.12 | Q42: Legacy high-cost borrowings largely repaid by FY26; refinance / Tier II growth resumes modestly (estimate).
B43: Investments / Deposits | F43: =Model!F157 -> 0.43683551 | G43: =Model!G157 -> 0.42259877 | H43: =Model!H157 -> 0.37247863 | I43: =Model!I157 -> 0.32021677 | J43: =Model!J157 -> 0.291931 | K43: 0.28 | L43: 0.28 | M43: 0.28 | N43: 0.28 | O43: 0.28 | Q43: FY26 29.2%, FY25 32.0%. SLR (18% of NDTL) plus buffer for LCR.
B44: Cash & Balances with RBI / Deposits | F44: =Model!F162 -> 0.10782401 | G44: =Model!G162 -> 0.074252902 | H44: =Model!H162 -> 0.055215992 | I44: =Model!I162 -> 0.055634404 | J44: =Model!J162 -> 0.038499524 | K44: 0.038 | L44: 0.038 | M44: 0.038 | N44: 0.038 | O44: 0.038 | Q44: FY26 3.85%, FY25 5.6%. CRR reduced to 3% of NDTL (RBI, 2025) plus operating cash.
B45: Minimum Bank Balances / Deposits | F45: =Model!F164 -> 0.041350087 | G45: =Model!G164 -> 0.021835445 | H45: =Model!H164 -> 0.0070057625 | I45: =Model!I164 -> 0.0042602461 | J45: =Model!J164 -> 0.0048400108 | K45: 0.007 | L45: 0.007 | M45: 0.007 | N45: 0.007 | O45: 0.007 | Q45: FY26 0.48%, FY25 0.43%. Minimum liquidity buffer; shortfall is funded by the liquidity facility (CFI revolver logic).
B46: Other Assets / Net Advances | F46: =Model!F251 -> 0.076870941 | G46: =Model!G251 -> 0.072700182 | H46: =Model!H251 -> 0.060190952 | I46: =Model!I251 -> 0.052466463 | J46: =Model!J251 -> 0.064565538 | K46: 0.06 | L46: 0.06 | M46: 0.06 | N46: 0.06 | O46: 0.06 | Q46: FY26 6.5%, FY25 5.2%, FY24 6.0%.
B47: Other Liabilities & Provisions / Deposits | F47: =Model!F253 -> 0.10016788 | G47: =Model!G253 -> 0.085531804 | H47: =Model!H253 -> 0.062030805 | I47: =Model!I253 -> 0.058320455 | J47: =Model!J253 -> 0.072444359 | K47: 0.07 | L47: 0.07 | M47: 0.07 | N47: 0.07 | O47: 0.07 | Q47: FY26 7.2%, FY25 5.8%.
B49: PRICING
B50: Yield on Investments | G50: =Model!G191 -> 0.060263793 | H50: =Model!H191 -> 0.060628294 | I50: =Model!I191 -> 0.068423469 | J50: =Model!J191 -> 0.071389331 | K50: 0.07 | L50: 0.07 | M50: 0.069 | N50: 0.069 | O50: 0.069 | Q50: FY26 calculated 7.14% on average investments; G-sec yields lower post 2025 rate cuts.
B51: Yield on Opening Cash & Inter-bank Balances | F51: =Model!F193 -> 0.041394268 | G51: =Model!G193 -> 0.0094155887 | H51: =Model!H193 -> 0.0067376795 | I51: =Model!I193 -> 0.0091785315 | J51: =Model!J193 -> 0.0086743643 | K51: 0.009 | L51: 0.009 | M51: 0.009 | N51: 0.009 | O51: 0.009 | Q51: FY26 0.87% on opening cash (CRR balances earn no interest).
B52: Other Interest Income / Avg Net Advances | G52: =Model!G195 -> 0.0013913471 | H52: =Model!H195 -> 0.0011275253 | I52: =Model!I195 -> 0.0010990288 | J52: =Model!J195 -> 0.0010499644 | K52: 0.001 | L52: 0.001 | M52: 0.001 | N52: 0.001 | O52: 0.001 | Q52: FY26 0.10%.
B53: Cost of CASA Deposits | K53: 0.045 | L53: 0.045 | M53: 0.045 | N53: 0.045 | O53: 0.045 | Q53: ESTIMATE – not separately disclosed in sources used. SA rates cut by 50–200 bps in Q4 FY26 (Investor Presentation). Calibrated so FY27 cost of funds ≈ 5.9% vs 6.22% FY26 calc.
B54: Cost of Term Deposits | K54: 0.071 | L54: 0.07 | M54: 0.07 | N54: 0.07 | O54: 0.07 | Q54: ESTIMATE – calibrated to reported cost of funds 6.00% in Q4 FY26.
B55: Cost of Borrowings | K55: 0.075 | L55: 0.075 | M55: 0.075 | N55: 0.075 | O55: 0.075 | Q55: ESTIMATE – mix of refinance, Tier II and infra bonds.
B56: Liquidity Facility Spread over Borrowing Cost | K56: 0.005 | L56: 0.005 | M56: 0.005 | N56: 0.005 | O56: 0.005 | Q56: Penalty spread on short-term liquidity funding (charged on opening balance – avoids circularity).
B58: INCOME & COSTS
B59: Other Income Growth | G59: =Model!G219 -> 0.38637944 | H59: =Model!H219 -> 0.3436401 | I59: =Model!I219 -> 0.16989503 | J59: =Model!J219 -> 0.12127815 | K59: 0.18 | L59: 0.17 | M59: 0.16 | N59: 0.15 | O59: 0.15 | Q59: FY26 +12.1% (incl. treasury loss); Q4 FY26 fee income +21% YoY (call). Fee growth tracks loan / card growth.
B60: Employee Cost Growth | G60: =Model!G223 -> 0.38778954 | H60: =Model!H223 -> 0.30738357 | I60: =Model!I223 -> 0.16706489 | J60: =Model!J223 -> 0.082668698 | K60: 0.14 | L60: 0.13 | M60: 0.13 | N60: 0.12 | O60: 0.12 | Q60: FY26 +8.3%, FY25 +16.7%. Branch / staff additions continue.
...

Sheet Model
B3: Income Statement
B5: All figures in INR crore unless stated | F5: =G5-1 -> 2022 | G5: =H5-1 -> 2023 | H5: =I5-1 -> 2024 | I5: =J5-1 -> 2025 | J5: =K5-1 -> 2026 | K5: =Inputs!$F$80 -> 2027 | L5: =K5+1 -> 2028 | M5: =L5+1 -> 2029 | N5: =M5+1 -> 2030 | O5: =N5+1 -> 2031
B6: {=CONCATENATE("Model Running: ",INDEX(Inputs!$B$11:$B$13,Inputs!$E$6)," Drivers")} -> Model Running: Base Case Drivers
B8: INTEREST EARNED
B9: Interest / Discount on Advances | F9: =Historicals!F8 -> 14174.01 | G9: =Historicals!G8 -> 19159.38 | H9: =Historicals!H8 -> 25915.89 | I9: =Historicals!I8 -> 30834.52 | J9: =Historicals!J8 -> 34198.63 | K9: =K190 -> 40404.285 | L9: =L190 -> 48115.027 | M9: =M190 -> 57033.467 | N9: =N190 -> 67036.197 | O9: =O190 -> 78739.856
B10: Income on Investments | F10: =Historicals!F9 -> 2615.37 | G10: =Historicals!G9 -> 3232.2 | H10: =Historicals!H9 -> 4117.69 | I10: =Historicals!I9 -> 5317.39 | J10: =Historicals!J9 -> 5949.65 | K10: =K192 -> 6529.5565 | L10: =L192 -> 7780.8304 | M10: =M192 -> 9238.3152 | N10: =N192 -> 11035.587 | O10: =O192 -> 13072.384
B11: Interest on RBI & Inter-bank Balances | F11: =Historicals!F10 -> 241.24 | G11: =Historicals!G10 -> 148.37 | H11: =Historicals!H10 -> 93.64 | I11: =Historicals!I10 -> 114.55 | J11: =Historicals!J10 -> 130.96 | K11: =K194 -> 114.86151 | L11: =L194 -> 145.49988 | M11: =M194 -> 192.10584 | N11: =N194 -> 211.26582 | O11: =O194 -> 282.19564
B12: Other Interest | F12: =Historicals!F11 -> 142.06 | G12: =Historicals!G11 -> 187.59 | H12: =Historicals!H11 -> 195.28 | I12: =Historicals!I11 -> 235.03 | J12: =Historicals!J11 -> 269.58 | K12: =K196 -> 308.42966 | L12: =L196 -> 370.11559 | M12: =M196 -> 442.1199 | N12: =N196 -> 523.72029 | O12: =O196 -> 615.15513
B13: Total Interest Earned | F13: =SUM(F9:F12) -> 17172.68 | G13: =SUM(G9:G12) -> 22727.54 | H13: =SUM(H9:H12) -> 30322.5 | I13: =SUM(I9:I12) -> 36501.49 | J13: =SUM(J9:J12) -> 40548.82 | K13: =SUM(K9:K12) -> 47357.133 | L13: =SUM(L9:L12) -> 56411.473 | M13: =SUM(M9:M12) -> 66906.008 | ... O13: =SUM(O9:O12) -> 92709.591
B15: Interest Expended | F15: =-Historicals!F14 -> -7466.52 | G15: =-Historicals!G14 -> -10092.21 | H15: =-Historicals!H14 -> -13871.75 | I15: =-Historicals!I14 -> -17209.52 | J15: =-Historicals!J14 -> -19333.55 | K15: =-K207 -> -21869.616 | L15: =-L207 -> -26046.558 | M15: =-M207 -> -31027.432 | N15: =-N207 -> -36962.498 | O15: =-O207 -> -43148.649
B16: Net Interest Income (NII) | F16: =F13+F15 -> 9706.16 | G16: =G13+G15 -> 12635.33 | H16: =H13+H15 -> 16450.75 | I16: =I13+I15 -> 19291.97 | J16: =J13+J15 -> 21215.27 | K16: =K13+K15 -> 25487.518 | L16: =L13+L15 -> 30364.915 | M16: =M13+M15 -> 35878.576 | ... O16: =O13+O15 -> 49560.942
B18: Other Income (Fees, Treasury & Other) | F18: =Historicals!F13 -> 3222.04 | G18: =Historicals!G13 -> 4466.97 | H18: =Historicals!H13 -> 6002 | I18: =Historicals!I13 -> 7021.71 | J18: =Historicals!J13 -> 7873.29 | K18: =K220 -> 9290.4822 | L18: =L220 -> 10869.864 | M18: =M220 -> 12609.042 | N18: =N220 -> 14500.399 | O18: =O220 -> 16675.459
B19: Total Net Income | F19: =F16+F18 -> 12928.2 | G19: =G16+G18 -> 17102.3 | H19: =H16+H18 -> 22452.75 | I19: =I16+I18 -> 26313.68 | J19: =J16+J18 -> 29088.56 | K19: =K16+K18 -> 34778 | L19: =L16+L18 -> 41234.779 | M19: =M16+M18 -> 48487.618 | ... O19: =O16+O18 -> 66236.401
B21: Employee Cost | F21: =-Historicals!F15 -> -2696.54 | G21: =-Historicals!G15 -> -3742.23 | H21: =-Historicals!H15 -> -4892.53 | I21: =-Historicals!I15 -> -5709.9 | J21: =-Historicals!J15 -> -6181.93 | K21: =-K224 -> -7047.4002 | L21: =-L224 -> -7963.5622 | M21: =-M224 -> -8998.8253 | N21: =-N224 -> -10078.684 | O21: =-O224 -> -11288.126
B22: Other Operating Expenses (incl. Depreciation) | F22: =-Historicals!F16 -> -6947.91 | G22: =-Historicals!G16 -> -8428.12 | H22: =-Historicals!H16 -> -11323.25 | I22: =-Historicals!I16 -> -13188.93 | J22: =-Historicals!J16 -> -15695.27 | K22: =-K226 -> -17892.608 | L22: =-L226 -> -20218.647 | M22: =-M226 -> -22847.071 | N22: =-N226 -> -25588.719 | O22: =-O226 -> -28659.366 | Q22: Depreciation is reported within other operating expenses (RBI format) and added back in the cash flow.
B23: Total Operating Expenses | F23: =SUM(F21:F22) -> -9644.45 | G23: =SUM(G21:G22) -> -12170.35 | H23: =SUM(H21:H22) -> -16215.78 | I23: =SUM(I21:I22) -> -18898.83 | J23: =SUM(J21:J22) -> -21877.2 | K23: =SUM(K21:K22) -> -24940.008 | L23: =SUM(L21:L22) -> -28182.209 | M23: =SUM(M21:M22) -> -31845.896 | ... O23: =SUM(O21:O22) -> -39947.492
B24: Operating Profit (PPOP) | F24: =F19+F23 -> 3283.75 | G24: =G19+G23 -> 4931.95 | H24: =H19+H23 -> 6236.97 | I24: =I19+I23 -> 7414.85 | J24: =J19+J23 -> 7211.36 | K24: =K19+K23 -> 9837.9917 | L24: =L19+L23 -> 13052.57 | M24: =M19+M23 -> 16641.722 | ... O24: =O19+O23 -> 26288.909
B26: Provisions (Other than Tax) & Contingencies | F26: =-Historicals!F17 -> -3108.58 | G26: =-Historicals!G17 -> -1664.82 | H26: =-Historicals!H17 -> -2381.65 | I26: =-Historicals!I17 -> -5514.73 | J26: =-Historicals!J17 -> -5378.55 | K26: =-K128 -> -5397.519 | L26: =-L128 -> -6106.9073 | M26: =-M128 -> -7073.9184 | N26: =-N128 -> -8117.6645 | O26: =-O128 -> -9534.9045
B27: Profit Before Tax | F27: =F24+F26 -> 175.17 | G27: =G24+G26 -> 3267.13 | H27: =H24+H26 -> 3855.32 | I27: =I24+I26 -> 1900.12 | J27: =J24+J26 -> 1832.81 | K27: =K24+K26 -> 4440.4727 | L27: =L24+L26 -> 6945.6626 | M27: =M24+M26 -> 9567.8034 | ... O27: =O24+O26 -> 16754.004
B29: Tax Expense | F29: =-Historicals!F18 -> -29.68 | G29: =-Historicals!G18 -> -830 | H29: =-Historicals!H18 -> -898.81 | I29: =-Historicals!I18 -> -375.27 | J29: =-Historicals!J18 -> -196.45 | K29: =-K264 -> -1117.667 | L29: =-L264 -> -1748.2233 | M29: =-M264 -> -2408.2161 | N29: =-N264 -> -3161.2522 | O29: =-O264 -> -4216.9829
B30: Net Profit (PAT) | F30: =F27+F29 -> 145.49 | G30: =G27+G29 -> 2437.13 | H30: =H27+H29 -> 2956.51 | I30: =I27+I29 -> 1524.85 | J30: =J27+J29 -> 1636.36 | K30: =K27+K29 -> 3322.8057 | L30: =L27+L29 -> 5197.4394 | M30: =M27+M29 -> 7159.5873 | ... O30: =O27+O29 -> 12537.022
B32: KEY RATIOS
B33: Net Interest Margin (NII / Avg Interest-Earning Assets) | G33: =G16/G210 -> 0.062154734 | H33: =H16/H210 -> 0.064690452 | I33: =I16/I210 -> 0.063178992 | J33: =J16/J210 -> 0.059926362 | K33: =K16/K210 -> 0.06124252 | L33: =L16/L210 -> 0.060726649 | M33: =M16/M210 -> 0.059955703 | N33: =N16/N210 -> 0.058846839 | O33: =O16/O210 -> 0.059148212
B34: Cost-to-Income Ratio | F34: =-F23/F19 -> 0.74600099 | G34: =-G23/G19 -> 0.71162066 | H34: =-H23/H19 -> 0.72221799 | I34: =-I23/I19 -> 0.71821311 | J34: =-J23/J19 -> 0.75208948 | K34: =-K23/K19 -> 0.71712025 | L34: =-L23/L19 -> 0.68345726 | M34: =-M23/M19 -> 0.65678409 | ... O34: =-O23/O19 -> 0.60310481
B35: Credit Cost (Provisions / Avg Net Advances) | G35: =-G26/G116 -> 0.0123479 | H35: =-H26/H116 -> 0.013751386 | I35: =-I26/I116 -> 0.025787547 | J35: =-J26/J116 -> 0.02094846 | K35: =-K26/K116 -> 0.0175 | L35: =-L26/L116 -> 0.0165 | M35: =-M26/M116 -> 0.016 | N35: =-N26/N116 -> 0.0155 | O35: =-O26/O116 -> 0.0155
B36: Effective Tax Rate | F36: =-F29/F27 -> 0.16943541 | G36: =-G29/G27 -> 0.2540456 | H36: =-H29/H27 -> 0.23313499 | I36: =-I29/I27 -> 0.19749805 | J36: =-J29/J27 -> 0.10718514 | K36: =-K29/K27 -> 0.2517 | L36: =-L29/L27 -> 0.2517 | M36: =-M29/M27 -> 0.2517 | ... O36: =-O29/O27 -> 0.2517
B37: Return on Average Assets (RoA) | G37: =G30/AVERAGE(F90,G90) -> 0.01133224 | H37: =H30/AVERAGE(G90,H90) -> 0.011030586 | I37: =I30/AVERAGE(H90,I90) -> 0.0047656496 | J37: =J30/AVERAGE(I90,J90) -> 0.0044011909 | K37: =K30/AVERAGE(J90,K90) -> 0.0075882619 | L37: =L30/AVERAGE(K90,L90) -> 0.0099024945 | M37: =M30/AVERAGE(L90,M90) -> 0.011406011 | N37: =N30/AVERAGE(M90,N90) -> 0.012607846 | O37: =O30/AVERAGE(N90,O90) -> 0.01427914
B38: Return on Average Equity (RoE) | G38: =G30/AVERAGE(F101,G101) -> 0.10431881 | H38: =H30/AVERAGE(G101,H101) -> 0.10215561 | I38: =I30/AVERAGE(H101,I101) -> 0.043418707 | J38: =J30/AVERAGE(I101,J101) -> 0.038308863 | K38: =K30/AVERAGE(J101,K101) -> 0.067943087 | L38: =L30/AVERAGE(K101,L101) -> 0.091893934 | M38: =M30/AVERAGE(L101,M101) -> 0.108728 | N38: =N30/AVERAGE(M101,N101) -> 0.12018229 | O38: =O30/AVERAGE(N101,O101) -> 0.1349131
B39: Cost of Funds (Interest Expended / Avg Deposits & Borrowings) | G39: =-G15/AVERAGE(F93+F94,G93+G94) -> 0.055998402 | H39: =-H15/AVERAGE(G93+G94,H93+H94) -> 0.061195125 | I39: =-I15/AVERAGE(H93+H94,I93+I94) -> 0.063439158 | J39: =-J15/AVERAGE(I93+I94,J93+J94) -> 0.062152234 | K39: =-K15/AVERAGE(J93+J94,K93+K94) -> 0.059795314 | L39: =-L15/AVERAGE(K93+K94,L93+L94) -> 0.059127673 | M39: =-M15/AVERAGE(L93+L94,M93+M94) -> 0.058721566 | N39: =-N15/AVERAGE(M93+M94,N93+N94) -> 0.058927675 | O39: =-O15/AVERAGE(N93+N94,O93+O94) -> 0.05849037
B42: Cash Flow Statement
B44: All figures in INR crore unless stated | F44: =F$5 -> 2022 | G44: =G$5 -> 2023 | H44: =H$5 -> 2024 | I44: =I$5 -> 2025 | J44: =J$5 -> 2026 | K44: =K$5 -> 2027 | L44: =L$5 -> 2028 | M44: =M$5 -> 2029 | ... O44: =O$5 -> 2031
B45: =B$6 -> Model Running: Base Case Drivers
B47: CASH FROM OPERATING ACTIVITIES
B48: Profit Before Tax | K48: =K27 -> 4440.4727 | L48: =L27 -> 6945.6626 | M48: =M27 -> 9567.8034 | N48: =N27 -> 12559.603 | O48: =O27 -> 16754.004 | Q48: Historical years show reported CFO / CFI / CFF subtotals (detail on Historicals tab).
B49: Add: Depreciation | K49: =K242 -> 818.3296 | L49: =L242 -> 825.30765 | M49: =M242 -> 856.93707 | N49: =N242 -> 908.01787 | O49: =O242 -> 975.28288
B50: Add: Provisions & Contingencies (Non-cash) | K50: =-K26 -> 5397.519 | L50: =-L26 -> 6106.9073 | M50: =-M26 -> 7073.9184 | N50: =-N26 -> 8117.6645 | O50: =-O26 -> 9534.9045
B51: Less: Direct Taxes Paid | K51: =K29 -> -1117.667 | L51: =L29 -> -1748.2233 | M51: =M29 -> -2408.2161 | N51: =N29 -> -3161.2522 | O51: =O29 -> -4216.9829
B52: (Increase) in Advances (Gross of Provisions) | K52: =-(K87-J87)-K50 -> -61475.639 | L52: =-(L87-K87)-L50 -> -73400.651 | M52: =-(M87-L87)-M50 -> -83788.787 | N52: =-(N87-M87)-N50 -> -94603.584 | O52: =-(O87-N87)-O50 -> -105918.66 | Q52: Net advances are shown net of provisions, so cash lent = increase in net advances + provisions charged.
B53: Increase in Deposits | K53: =K93-J93 -> 64784.401 | L53: =L93-K93 -> 75444.38 | M53: =M93-L93 -> 86940.666 | N53: =N93-M93 -> 99112.359 | O53: =O93-N93 -> 111736.14
B54: (Increase) in Investments | K54: =-(K86-J86) -> -14626.256 | L54: =-(L86-K86) -> -21124.426 | M54: =-(M86-L86) -> -24343.387 | N54: =-(N86-M86) -> -27751.461 | O54: =-(O86-N86) -> -31286.12
...

Sheet DCF Valuation
B3: Valuation: Residual Income Model (RIM)
B5: All figures in INR crore unless stated | F5: =Model!F$5 -> 2022 | G5: =Model!G$5 -> 2023 | H5: =Model!H$5 -> 2024 | I5: =Model!I$5 -> 2025 | J5: =Model!J$5 -> 2026 | K5: =Model!K$5 -> 2027 | L5: =Model!L$5 -> 2028 | M5: =Model!M$5 -> 2029 | ... O5: =Model!O$5 -> 2031 | Q5: Source / rationale
B6: =Model!B6 -> Model Running: Base Case Drivers
B8: METHODOLOGY
B9: Banks are valued on equity, not enterprise value: deposits and borrowings are operating inputs, so FCFF/EV frameworks are not meaningful.
B10: Residual Income Model: Equity value = Opening book value + PV of (Net profit – Cost of equity × Opening equity) + PV of terminal residual income.
B11: RIM is preferred over a DDM because the bank pays a token dividend (~13–15% payout) and retains most earnings; book value and ROE drive value.
B12: Inputs: net profit, dividends, equity issuance and shareholders' funds link directly to the Model tab (clean-surplus check below). Discounting is end-of-year from 31-Mar-2026, then rolled forward to the valuation date.
B14: VALUATION ASSUMPTIONS
B15: Valuation Date | F15: 46308 | Q15: Date of the market data used (G-sec yield and share price).
B16: Valuation Base Date (latest audited balance sheet) | F16: =DATE(Model!$J$5,3,31) -> 46112 | Q16: 31-Mar of last actual year on Model tab (FY26A). Opening book value is taken at this date.
B17: Current Market Price (NSE) | D17: ₹ | F17: ='Comparable Company Analysis'!$F$11 -> 78.83 | Q17: Linked to Comparable Company Analysis!F11 (single price input for both methods). Price is an UNOFFICIAL quote – verify against the NSE official close before use.
B18: Face Value per Share | D18: ₹ | F18: 10 | Q18: Face value ₹10 per share (audited results, item 15).
B19: Shares Outstanding (basic) | D19: crore | F19: =Historicals!$J$24/$F$18 -> 860.17 | Q19: Paid-up capital at 31-Mar-2026 ÷ face value. Basic count; ESOP dilution (~1% per diluted EPS) not included.
B20: Dividend per Share Paid after Base Date | D20: ₹ | F20: 0.25 | Q20: FY26 dividend of ₹0.25/share proposed (Q4 FY26 results). Assumed paid before the valuation date – record/payment date not verified.
B21: Assumed Issue Price for New Equity | D21: ₹/share | F21: =IF($F$17="","",$F$17) -> 78.83 | Q21: Used only to convert Model equity raises (Inputs row 74) into new shares for forecast BVPS/EPS. Defaults to market price; overwrite if needed. Does not affect intrinsic value (see note in row 58).
B23: COST OF EQUITY (CAPM)
B24: Risk-free Rate (India 10Y G-sec) | F24: 0.0735 | Q24: India 10-year G-sec yield ~7.35% on 13-Oct-2026 (market data; verify against FBIL/CCIL). Local-currency rate, consistent with INR cash flows.
B25: Equity Beta | F25: 1.14 | Q25: 3-year beta vs index ~1.14 (1-year ~1.21–1.25) per broker data pages – unofficial; verify on Bloomberg/NSE. Above 1 given mid-cap, high-growth retail book.
B26: Equity Risk Premium (India) | F26: 0.07 | Q26: India ERP 7.00% (range 6.5–7.5%), Incwert India ERP Study, Jan-2026 – designed for use with the Indian G-sec rate.
B27: Cost of Equity (Ke) | F27: =F24+F25*F26 -> 0.1533 | Q27: Ke = Rf + β × ERP.
B29: TERMINAL VALUE
B30: Terminal Growth Rate of Residual Income (g) | F30: 0.05 | Q30: 5.0%: below India's long-run nominal GDP growth (~10%) since excess returns are competed away over time and the bank's growth converges to system growth. Must be < Ke.
B31: Terminal ROE Override (blank = use FY31F ROE) | Q31: Optional. Leave blank to use the forecast FY31 ROE on opening equity (row 47). Enter e.g. a long-run target ROE to test.
B32: Terminal ROE Applied | F32: =IF($F$31="",$O$47,$F$31) -> 0.14350492 | Q32: Sustainable ROE earned on FY31 closing equity in perpetuity.
B33: Check: Ke > g | F33: =IF($F$27>$F$30,"OK","ERROR") -> OK | Q33: Gordon-growth terminal value only valid when Ke exceeds g.
B36: HISTORICAL & FORECAST METRICS
B37: Net Profit (PAT) | F37: =Model!F30 -> 145.49 | G37: =Model!G30 -> 2437.13 | H37: =Model!H30 -> 2956.51 | I37: =Model!I30 -> 1524.85 | J37: =Model!J30 -> 1636.36 | K37: =Model!K30 -> 3322.8057 | L37: =Model!L30 -> 5197.4394 | M37: =Model!M30 -> 7159.5873 | ... O37: =Model!O30 -> 12537.022 | Q37: Model IS row 30.
B38: Dividends Paid | K38: =Model!K280 -> 215.0425 | L38: =Model!L280 -> 498.42085 | M38: =Model!M280 -> 779.6159 | N38: =Model!N280 -> 1073.9381 | O38: =Model!O280 -> 1409.7527 | Q38: Model equity schedule row 280 (payout × prior-year PAT). Historical dividends not split out on Historicals tab.
B39: Equity Issuance | K39: =Model!K274 -> 0 | L39: =Model!L274 -> 7500 | M39: =Model!M274 -> 0 | N39: =Model!N274 -> 10000 | O39: =Model!O274 -> 0 | Q39: Model row 274 (Inputs row 74 – illustrative raises).
B40: Closing Shareholders' Equity | F40: =Model!F101 -> 21003.48 | G40: =Model!G101 -> 25721.17 | H40: =Model!H101 -> 32161.31 | I40: =Model!I101 -> 38078 | J40: =Model!J101 -> 47351.84 | K40: =Model!K101 -> 50459.603 | L40: =Model!L101 -> 62658.622 | M40: =Model!M101 -> 69038.593 | ... O40: =Model!O101 -> 98490.275 | Q40: Model BS row 101 (capital + ESOP outstanding + reserves).
B41: Opening Shareholders' Equity | G41: =F40 -> 21003.48 | H41: =G40 -> 25721.17 | I41: =H40 -> 32161.31 | J41: =I40 -> 38078 | K41: =J40 -> 47351.84 | L41: =K40 -> 50459.603 | M41: =L40 -> 62658.622 | N41: =M40 -> 69038.593 | O41: =N40 -> 87363.006
B42: Clean-surplus Check (Open + PAT – Div + Issue – Close) | K42: =ROUND(K41+K37-K38+K39-K40,0) -> 0 | L42: =ROUND(L41+L37-L38+L39-L40,0) -> 0 | M42: =ROUND(M41+M37-M38+M39-M40,0) -> 0 | N42: =ROUND(N41+N37-N38+N39-N40,0) -> 0 | O42: =ROUND(O41+O37-O38+O39-O40,0) -> 0 | Q42: Must be 0: confirms all equity movements are captured, so RIM equals DDM (no double counting).
B44: Shares Outstanding (year-end) | F44: =Historicals!F24/$F$18 -> 621.771 | G44: =Historicals!G24/$F$18 -> 661.812 | H44: =Historicals!H24/$F$18 -> 706.992 | I44: =Historicals!I24/$F$18 -> 732.211 | J44: =Historicals!J24/$F$18 -> 860.17 | K44: =IF($F$21="","",J44+K39/$F$21) -> 860.17 | L44: =IF($F$21="","",K44+L39/$F$21) -> 955.31144 | M44: =IF($F$21="","",L44+M39/$F$21) -> 955.31144 | N44: =IF($F$21="","",M44+N39/$F$21) -> 1082.1667 | O44: =IF($F$21="","",N44+O39/$F$21) -> 1082.1667 | Q44: Forecast: prior year + equity raised ÷ assumed issue price (F21). Blank until a price is entered.
B45: Book Value per Share (BVPS) | F45: =IF(F44="","",F40/F44) -> 33.780089 | G45: =IF(G44="","",G40/G44) -> 38.864768 | H45: =IF(H44="","",H40/H44) -> 45.490345 | I45: =IF(I44="","",I40/I44) -> 52.004135 | J45: =IF(J44="","",J40/J44) -> 55.049397 | K45: =IF(K44="","",K40/K44) -> 58.662361 | L45: =IF(L44="","",L40/L44) -> 65.589732 | M45: =IF(M44="","",M40/M44) -> 72.268152 | ... O45: =IF(O44="","",O40/O44) -> 91.01211 | Q45: Closing equity ÷ year-end shares (₹).
B46: Earnings per Share (EPS) | F46: =IF(F44="","",F37/F44) -> 0.2339929 | G46: =IF(G44="","",G37/G44) -> 3.682511 | H46: =IF(H44="","",H37/H44) -> 4.1818154 | I46: =IF(I44="","",I37/I44) -> 2.0825281 | J46: =IF(J44="","",J37/J44) -> 1.9023681 | K46: =IF(K44="","",K37/K44) -> 3.8629639 | L46: =IF(L44="","",L37/L44) -> 5.4405706 | M46: =IF(M44="","",M37/M44) -> 7.4945059 | ... O46: =IF(O44="","",O37/O44) -> 11.585111 | Q46: PAT ÷ year-end shares (₹) – approximation; reported EPS uses weighted average shares.
B47: ROE on Opening Equity | G47: =G37/G41 -> 0.11603458 | H47: =H37/H41 -> 0.11494462 | I47: =I37/I41 -> 0.047412559 | J47: =J37/J41 -> 0.042973896 | K47: =K37/K41 -> 0.070172684 | L47: =L37/L41 -> 0.10300199 | M47: =M37/M41 -> 0.1142634 | N47: =N37/N41 -> 0.13613185 | O47: =O37/O41 -> 0.14350492 | Q47: PAT ÷ opening equity – the return definition consistent with the RIM equity charge (Model row 38 uses average equity).
B48: Dividend per Share | K48: =IF(J44="","",K38/J44) -> 0.25 | L48: =IF(K44="","",L38/K44) -> 0.57944459 | M48: =IF(L44="","",M38/L44) -> 0.81608559 | N48: =IF(M44="","",N38/M44) -> 1.1241759 | O48: =IF(N44="","",O38/N44) -> 1.3027131 | Q48: Dividend paid in year ÷ prior year-end shares (₹).
B50: RESIDUAL INCOME (EXPLICIT FORECAST FY27F–FY31F)
B51: Opening Shareholders' Equity (Bt-1) | K51: =K41 -> 47351.84 | L51: =L41 -> 50459.603 | M51: =M41 -> 62658.622 | N51: =N41 -> 69038.593 | O51: =O41 -> 87363.006
...

Sheet Comparable Company Analysis
B3: Comparable Company Analysis: IDFC FIRST Bank vs Listed Indian Bank Peers
B5: All figures in INR crore unless stated; per-share figures in ₹ | R5: Source / rationale
B6: Blue = hard-coded input (sources in cell notes); Green = link to other tabs; Black = formula. Peer data are FY26A (year ended 31-Mar-2026) audited results; prices are unofficial quotes – verify on NSE.
B8: VALUATION PARAMETERS
B9: Valuation Date | F9: ='DCF Valuation'!$F$15 -> 46308 | R9: Linked to DCF Valuation tab so both methods share one valuation date.
B10: Financial Period for Trailing Multiples | F10: FY26A | R10: Latest audited full year for all banks: year ended 31-Mar-2026.
B11: IDFC FIRST Bank Market Price (₹) | F11: 78.83 | R11: UNOFFICIAL quote – NSE close 13-Oct-2026 per Value Research (corroborated by Bajaj Finserv previous close). Verify on nseindia.com. Single price input: DCF Valuation!F17 links here.
B12: Adjustment to IDFC FY26A PAT for One-offs (₹ cr, post-tax) | F12: 0 | R12: Default 0 = reported PAT. Management's Q4 FY26 normalised PAT (₹746 cr) vs reported (₹319 cr) implies ~₹427 cr of one-offs (fraud incident, treasury loss, tax refund) – enter to test a normalised P/E.
B14: PEER SELECTION
B15: Bank | C15: Ticker (NSE) | D15: Type | E15: Benchmark? | F15: Rationale
B16: Federal Bank | C16: FEDERALBNK | D16: Mid-size private | E16: Core | F16: Closest on size (₹3.9 lakh cr assets) and diversified retail/SME/NRI mix; lower NIM, much stronger RoA and asset quality than IDFC.
B17: AU Small Finance Bank | C17: AUBANK | D17: SFB → universal | E17: Core | F17: Retail-led, high-yield secured lending like IDFC's RAM book; NIM ~6%. Trades at a premium (high ROE, growth); in-principle universal-bank approval.
B18: Bandhan Bank | C18: BANDHANBNK | D18: Mid-size private | E18: Core | F18: High-NIM (6.1%), retail/microfinance-heavy, transforming to secured lending; weak ROE like IDFC. Price +9% on 13-Oct-2026 on stake-sale rumour (bank denied).
B19: IndusInd Bank | C19: INDUSINDBK | D19: Large private | E19: P/B only | F19: Similar size and retail/vehicle/MFI exposure; FY26 earnings depressed by accounting-lapse aftermath (ROE ~1.4%), so P/E (~77x) is not meaningful – excluded from P/E benchmark.
B20: RBL Bank | C20: RBLBANK | D20: Mid-size private | E20: Excluded | F20: Emirates NBD acquired 60% (Jun-2026) via large primary issuance; share count and book changed materially after FY26, so FY26 BVPS/EPS are not comparable with today's price.
B21: HDFC / ICICI / Axis Bank | C21: — | D21: Large private | E21: Not used | F21: Secondary benchmarks only: far larger, lower-cost deposit franchises with mature ROE (15–18%). Not collected in this version; would bias multiples upward.
B23: MARKET DATA & REPORTED FINANCIALS (FY26A)
B24: Bank | C24: Basis | D24: Price (₹) | E24: Face Value (₹) | F24: Paid-up Capital | G24: Shares (cr) | H24: Market Cap | I24: Shareholders' Equity | J24: Net Profit FY26 | K24: Total Income FY26 | L24: Total Assets | M24: BVPS (₹) | N24: EPS (₹) | O24: Reported Basic EPS (₹) | R24: Definitions: Shares = paid-up capital ÷ face value. Equity = capital + reserves (+ ESOP outstanding where reported); excludes warrant money/preference capital. EPS = PAT ÷ year-end shares (basic, simple).
B25: Federal Bank | C25: Standalone | D25: 329.4 | E25: 2 | F25: 492.86 | G25: =F25/E25 -> 246.43 | H25: =D25*G25 -> 81174.042 | I25: 37155.94 | J25: 4117.32 | K25: 32135.77 | L25: 387521.49 | M25: =I25/G25 -> 150.77685 | N25: =J25/G25 -> 16.707868 | O25: 16.74 | R25: Federal: equity excludes ₹1,549 cr share-warrant subscription money (Blackstone warrants not yet converted). FV ₹2.
B26: AU Small Finance Bank | C26: Standalone | D26: 991.5 | E26: 10 | F26: 748.27 | G26: =F26/E26 -> 74.827 | H26: =D26*G26 -> 74190.97 | I26: 19974 | J26: 2641.25 | K26: 21614.28 | L26: 191797.47 | M26: =I26/G26 -> 266.93573 | N26: =J26/G26 -> 35.298088 | O26: 35.4 | R26: AU: equity = shareholders' funds per press release; total income and EPS are from an unofficial results summary.
B27: Bandhan Bank | C27: Standalone | D27: 172 | E27: 10 | F27: 1610.97 | G27: =F27/E27 -> 161.097 | H27: =D27*G27 -> 27708.684 | I27: 25574.9 | J27: 1223.56 | K27: 24423.14 | L27: 211123.73 | M27: =I27/G27 -> 158.75466 | N27: =J27/G27 -> 7.5951756 | O27: 7.6 | R27: Bandhan: no subsidiaries, so standalone = group.
B28: IndusInd Bank | C28: Consolidated | D28: 877.35 | E28: 10 | F28: 779.05 | G28: =F28/E28 -> 77.905 | H28: =D28*G28 -> 68349.952 | I28: 62866.98 | J28: 889.34 | K28: 53480 | L28: 543394 | M28: =I28/G28 -> 806.96977 | N28: =J28/G28 -> 11.415699 | O28: n/a | R28: IndusInd: CONSOLIDATED (press release reports consolidated headline figures; standalone PAT ₹933 cr per unofficial summary). Share count from paid-up capital Jun-2025 (latest official found).
B30: IDFC FIRST Bank (subject) | C30: Standalone | D30: =$F$11 -> 78.83 | E30: ='DCF Valuation'!$F$18 -> 10 | F30: =Historicals!$J$24 -> 8601.7 | G30: =F30/E30 -> 860.17 | H30: =D30*G30 -> 67807.201 | I30: =Model!$J$101 -> 47351.84 | J30: =Model!$J$30+$F$12 -> 1636.36 | K30: =Historicals!$J$12+Historicals!$J$13 -> 48422.11 | L30: =Model!$J$90 -> 399780.09 | M30: =I30/G30 -> 55.049397 | N30: =J30/G30 -> 1.9023681 | O30: 1.93 | R30: Links: equity Model J101, PAT Model J30 (+ F12 adjustment), assets Model J90, capital Historicals J24, total income = interest earned + other income.
B33: VALUATION MULTIPLES & OPERATING METRICS
B34: Bank | C34: In P/B Set? (Y/N) | D34: In P/E Set? (Y/N) | E34: P/B (x) | F34: P/E (x) | G34: ROE (PAT ÷ Closing Equity) | H34: ROA (PAT ÷ Closing Assets) | I34: ROA (Reported) | J34: NIM (Reported) | K34: GNPA % | L34: NNPA % | M34: CRAR % | N34: Market Cap (₹ cr) | O34: P/B (benchmark set) | P34: P/E (benchmark set) | R34: Benchmark set flags (C:D) are editable. Mean/median for P/B and P/E use only flagged peers; operating-metric averages use all four peers. ROE uses closing equity because prior-year equity was not collected for every peer.
B35: =B25 -> Federal Bank | C35: Y | D35: Y | E35: =D25/M25 -> 2.1846855 | F35: =IF(N25<=0,"n/m",D25/N25) -> 19.715262 | G35: =J25/I25 -> 0.11081189 | H35: =J25/L25 -> 0.010624753 | I35: 0.0115 | J35: n/a | K35: 0.0162 | L35: 0.002 | M35: 0.1725 | N35: =H25 -> 81174.042 | O35: =IF(C35="Y",E35,"") -> 2.1846855 | P35: =IF(AND(D35="Y",ISNUMBER(F35)),F35,"") -> 19.715262 | R35: NIM: AU, IndusInd = Q4 FY26; Bandhan, IDFC = FY26; Federal NIM not found in sources used (n/a). Definitions differ by bank – use for context only.
B36: =B26 -> AU Small Finance Bank | C36: Y | D36: Y | E36: =D26/M26 -> 3.7143772 | F36: =IF(N26<=0,"n/m",D26/N26) -> 28.08934 | G36: =J26/I26 -> 0.1322344 | H36: =J26/L26 -> 0.013771037 | I36: 0.0157 | J36: 0.0596 | K36: 0.0203 | L36: 0.0074 | M36: 0.1868 | N36: =H26 -> 74190.97 | O36: =IF(C36="Y",E36,"") -> 3.7143772 | P36: =IF(AND(D36="Y",ISNUMBER(F36)),F36,"") -> 28.08934
B37: =B27 -> Bandhan Bank | C37: Y | D37: Y | E37: =D27/M27 -> 1.0834327 | F37: =IF(N27<=0,"n/m",D27/N27) -> 22.645954 | G37: =J27/I27 -> 0.04784222 | H37: =J27/L27 -> 0.0057954641 | I37: 0.0064 | J37: 0.061 | K37: 0.0327 | L37: 0.0097 | M37: 0.18 | N37: =H27 -> 27708.684 | O37: =IF(C37="Y",E37,"") -> 1.0834327 | P37: =IF(AND(D37="Y",ISNUMBER(F37)),F37,"") -> 22.645954
B38: =B28 -> IndusInd Bank | C38: Y | D38: N | E38: =D28/M28 -> 1.0872154 | F38: =IF(N28<=0,"n/m",D28/N28) -> 76.854692 | G38: =J28/I28 -> 0.014146377 | H38: =J28/L28 -> 0.0016366393 | I38: n/a | J38: 0.0339 | K38: 0.0343 | L38: 0.01 | M38: 0.1748 | N38: =H28 -> 68349.952 | O38: =IF(C38="Y",E38,"") -> 1.0872154 | P38: =IF(AND(D38="Y",ISNUMBER(F38)),F38,"") | R38: IndusInd excluded from P/E set: FY26 PAT depressed by derivative/MFI accounting-lapse aftermath; P/E ~77x is an outlier. Reported FY ROA not found (Q4 annualised 0.45%).
B39: Mean – benchmark set | E39: =AVERAGE($O$35:$O$38) -> 2.0174277 | F39: =AVERAGE($P$35:$P$38) -> 23.483519 | G39: =AVERAGE(G35:G38) -> 0.076258723 | H39: =AVERAGE(H35:H38) -> 0.0079569732 | I39: =AVERAGE(I35:I38) -> 0.0112 | J39: =AVERAGE(J35:J38) -> 0.0515 | K39: =AVERAGE(K35:K38) -> 0.025875 | L39: =AVERAGE(L35:L38) -> 0.007275 | M39: =AVERAGE(M35:M38) -> 0.178525 | N39: =AVERAGE(N35:N38) -> 62855.912
B40: Median – benchmark set (primary) | E40: =MEDIAN($O$35:$O$38) -> 1.6359505 | F40: =MEDIAN($P$35:$P$38) -> 22.645954 | G40: =MEDIAN(G35:G38) -> 0.079327056 | H40: =MEDIAN(H35:H38) -> 0.0082101084 | I40: =MEDIAN(I35:I38) -> 0.0115 | J40: =MEDIAN(J35:J38) -> 0.0596 | K40: =MEDIAN(K35:K38) -> 0.0265 | L40: =MEDIAN(L35:L38) -> 0.00855 | M40: =MEDIAN(M35:M38) -> 0.1774 | N40: =MEDIAN(N35:N38) -> 71270.461
B41: =B30 -> IDFC FIRST Bank (subject) | C41: Subject | D41: Subject | E41: =D30/M30 -> 1.4319866 | F41: =IF(N30<=0,"n/m",D30/N30) -> 41.437826 | G41: =J30/I30 -> 0.034557474 | H41: =J30/L30 -> 0.0040931503 | I41: 0.0044 | J41: 0.0575 | K41: =Historicals!$J$56 -> 0.0161 | L41: =Historicals!$J$57 -> 0.0048 | M41: =Historicals!$J$58 -> 0.156 | N41: =H30 -> 67807.201 | R41: IDFC ROA 0.44% (audited results, item 17v); NIM 5.75% FY26 (investor presentation, gross of IBPC & sell-down).
B44: FORWARD MULTIPLES (FY27E) – PEER CONSENSUS INPUTS
B45: Bank | C45: FY27E EPS (₹) | D45: FY27E BVPS (₹) | E45: Forward P/E (x) | F45: Forward P/B (x) | G45: In Set? | R45: PEER FORWARD DATA NOT ENTERED: FY27E consensus EPS/BVPS for peers could not be sourced from official documents (companies do not publish forecasts). Enter broker/Bloomberg consensus to activate forward multiples; forward implied prices stay 'n/a' until then. Do not apply trailing peer multiples to IDFC forecasts – periods would not match.
B46: =B25 -> Federal Bank | E46: =IF(AND(ISNUMBER(C46),D35="Y"),D25/C46,"") | F46: =IF(AND(ISNUMBER(D46),C35="Y"),D25/D46,"") | G46: =C35&"/"&D35 -> Y/Y
B47: =B26 -> AU Small Finance Bank | E47: =IF(AND(ISNUMBER(C47),D36="Y"),D26/C47,"") | F47: =IF(AND(ISNUMBER(D47),C36="Y"),D26/D47,"") | G47: =C36&"/"&D36 -> Y/Y
B48: =B27 -> Bandhan Bank | E48: =IF(AND(ISNUMBER(C48),D37="Y"),D27/C48,"") | F48: =IF(AND(ISNUMBER(D48),C37="Y"),D27/D48,"") | G48: =C37&"/"&D37 -> Y/Y
B49: =B28 -> IndusInd Bank | E49: =IF(AND(ISNUMBER(C49),D38="Y"),D28/C49,"") | F49: =IF(AND(ISNUMBER(D49),C38="Y"),D28/D49,"") | G49: =C38&"/"&D38 -> Y/N
B50: Median – forward benchmark set | E50: =IF(COUNT(E46:E49)=0,"n/a",MEDIAN(E46:E49)) -> n/a | F50: =IF(COUNT(F46:F49)=0,"n/a",MEDIAN(F46:F49)) -> n/a
B52: IDFC FIRST Bank – FY27F (from Model)
...

Sheet Historicals
B3: Historical Financials (Reported, Standalone)
B5: All figures in INR crore unless stated (reported in INR lakh; converted ÷100) | F5: =G5-1 -> 2022 | G5: =H5-1 -> 2023 | H5: =I5-1 -> 2024 | I5: =J5-1 -> 2025 | J5: =Inputs!$F$80-1 -> 2026
B6: Fiscal year ending 31 March. Blue = reported figures from official filings (see cell notes). Black = check formulas.
B7: INCOME STATEMENT (RBI SCHEDULE FORMAT)
B8: Interest / Discount on Advances & Bills | F8: 14174.01 | G8: 19159.38 | H8: 25915.89 | I8: 30834.52 | J8: 34198.63
B9: Income on Investments | F9: 2615.37 | G9: 3232.2 | H9: 4117.69 | I9: 5317.39 | J9: 5949.65
B10: Interest on Balances with RBI & Inter-bank Funds | F10: 241.24 | G10: 148.37 | H10: 93.64 | I10: 114.55 | J10: 130.96
B11: Other Interest | F11: 142.06 | G11: 187.59 | H11: 195.28 | I11: 235.03 | J11: 269.58
B12: Total Interest Earned | F12: =SUM(F8:F11) -> 17172.68 | G12: =SUM(G8:G11) -> 22727.54 | H12: =SUM(H8:H11) -> 30322.5 | I12: =SUM(I8:I11) -> 36501.49 | J12: =SUM(J8:J11) -> 40548.82
B13: Other Income | F13: 3222.04 | G13: 4466.97 | H13: 6002 | I13: 7021.71 | J13: 7873.29
B14: Interest Expended | F14: 7466.52 | G14: 10092.21 | H14: 13871.75 | I14: 17209.52 | J14: 19333.55
B15: Employee Cost | F15: 2696.54 | G15: 3742.23 | H15: 4892.53 | I15: 5709.9 | J15: 6181.93
B16: Other Operating Expenses | F16: 6947.91 | G16: 8428.12 | H16: 11323.25 | I16: 13188.93 | J16: 15695.27
B17: Provisions (Other than Tax) & Contingencies | F17: 3108.58 | G17: 1664.82 | H17: 2381.65 | I17: 5514.73 | J17: 5378.55
B18: Tax Expense | F18: 29.68 | G18: 830 | H18: 898.81 | I18: 375.27 | J18: 196.45
B19: Net Profit (Calculated) | F19: =F12+F13-F14-F15-F16-F17-F18 -> 145.49 | G19: =G12+G13-G14-G15-G16-G17-G18 -> 2437.13 | H19: =H12+H13-H14-H15-H16-H17-H18 -> 2956.51 | I19: =I12+I13-I14-I15-I16-I17-I18 -> 1524.85 | J19: =J12+J13-J14-J15-J16-J17-J18 -> 1636.36
B20: Net Profit (Reported) | F20: 145.49 | G20: 2437.13 | H20: 2956.51 | I20: 1524.85 | J20: 1636.36
B21: Check | F21: =ROUND(F19-F20,0) -> 0 | G21: =ROUND(G19-G20,0) -> 0 | H21: =ROUND(H19-H20,0) -> 0 | I21: =ROUND(I19-I20,0) -> 0 | J21: =ROUND(J19-J20,0) -> 0
B23: BALANCE SHEET
B24: Capital | F24: 6217.71 | G24: 6618.12 | H24: 7069.92 | I24: 7322.11 | J24: 8601.7
B25: Employees Stock Options Outstanding | F25: 16.12 | G25: 37.12 | H25: 58.93 | I25: 148.72 | J25: 287.87
B26: Reserves & Surplus | F26: 14769.65 | G26: 19065.93 | H26: 25032.46 | I26: 30607.17 | J26: 38462.27
B27: Deposits | F27: 105634.36 | G27: 144637.31 | H27: 200576.31 | I27: 252065.25 | J27: 294474.55
B28: Borrowings | F28: 52962.6 | G28: 57212.09 | H28: 50935.57 | I28: 38974.84 | J28: 36620.68
B29: Other Liabilities & Provisions | F29: 10581.17 | G29: 12371.09 | H29: 12441.91 | I29: 14700.56 | J29: 21333.02
B30: Total Capital & Liabilities | F30: =SUM(F24:F29) -> 190181.61 | G30: =SUM(G24:G29) -> 239941.66 | H30: =SUM(H24:H29) -> 296115.1 | I30: =SUM(I24:I29) -> 343818.65 | J30: =SUM(J24:J29) -> 399780.09
B31: Cash & Balances with RBI | F31: 11389.92 | G31: 10739.74 | H31: 11075.02 | I31: 14023.5 | J31: 11337.13
B32: Balances with Banks & Money at Call / Short Notice | F32: 4367.99 | G32: 3158.22 | H32: 1405.19 | I32: 1073.86 | J32: 1425.26
B33: Investments | F33: 46144.84 | G33: 61123.55 | H33: 74710.39 | I33: 80715.52 | J33: 85966.25
B34: Advances (Net) | F34: 117857.8 | G34: 151794.53 | H34: 194592.37 | I34: 233112.53 | J34: 280390.6
B35: Fixed Assets | F35: 1361.22 | G35: 2090.13 | H35: 2619.43 | I35: 2662.65 | J35: 2557.28
B36: Other Assets | F36: 9059.84 | G36: 11035.49 | H36: 11712.7 | I36: 12230.59 | J36: 18103.57
B37: Total Assets | F37: =SUM(F31:F36) -> 190181.61 | G37: =SUM(G31:G36) -> 239941.66 | H37: =SUM(H31:H36) -> 296115.1 | I37: =SUM(I31:I36) -> 343818.65 | J37: =SUM(J31:J36) -> 399780.09
B38: Check | F38: =ROUND(F30-F37,0) -> 0 | G38: =ROUND(G30-G37,0) -> 0 | H38: =ROUND(H30-H37,0) -> 0 | I38: =ROUND(I30-I37,0) -> 0 | J38: =ROUND(J30-J37,0) -> 0
B40: CASH FLOW STATEMENT (REPORTED SUBTOTALS)
B41: Net Cash from Operating Activities | F41: 2603.92 | G41: 3599.65 | H41: 11327.96 | I41: 14394.54 | J41: 6915.04
B42: Net Cash from Investing Activities | F42: -2884.46 | G42: -11968.64 | H42: -9791.79 | I42: -3399.22 | J42: -14241.28
B43: Net Cash from Financing Activities | F43: 10210.59 | G43: 6509.04 | H43: -2953.92 | I43: -8682.05 | J43: 4969.12
B44: Effect of FX Translation Reserve | F44: 0 | G44: 0 | H44: 0 | I44: 4.95 | J44: 22.15
B45: Cash Acquired on Amalgamation (IDFC Ltd) | D45: FY25: merger of IDFC Ltd into the Bank (effective 1-Oct-2024) | F45: 0 | G45: 0 | H45: 0 | I45: 298.93 | J45: 0
...
